8=FIX.4.49=001496335=X49=SPOT56=BMDWATCH34=152=20251204-17:25:12.114540262=DEPTH_STREAM268=160279=1269=0270=93165.14000000271=6.7256900055=BTCUSDT25043=8243034669425044=82430347121279=1269=0270=93165.13000000271=0.0000000055=BTCUSDT25043=8243034669425044=82430347121279=1269=0270=93165.12000000271=0.0000000055=BTCUSDT25043=8243034669425044=82430347121279=1269=0270=93165.09000000271=0.0000600055=BTCUSDT25043=8243034669425044=82430347121279=1269=0270=93164.79000000271=0.0000600055=BTCUSDT25043=8243034669425044=82430347121279=1269=0270=93164.56000000271=0.5265000055=BTCUSDT25043=8243034669425044=82430347121279=1269=0270=93164.55000000271=2.4146900055=BTCUSDT25043=8243034669425044=82430347121279=1269=0270=93164.50000000271=0.0000600055=BTCUSDT25043=8243034669425044=82430347121279=1269=0270=93164.21000000271=0.0025000055=BTCUSDT25043=8243034669425044=82430347121279=1269=0270=93164.20000000271=0.0000000055=BTCUSDT25043=8243034669425044=82430347121279=1269=0270=93163.75000000271=0.0000600055=BTCUSDT25043=8243034669425044=82430347121279=1269=0270=93163.68000000271=0.0000000055=BTCUSDT25043=8243034669425044=82430347121279=1269=0270=93163.67000000271=0.0002700055=BTCUSDT25043=8243034669425044=82430347121279=1269=0270=93163.50000000271=0.0000000055=BTCUSDT25043=8243034669425044=82430347121279=1269=0270=93163.46000000271=0.0000000055=BTCUSDT25043=8243034669425044=82430347121279=1269=0270=93163.45000000271=0.0000000055=BTCUSDT25043=8243034669425044=82430347121279=1269=0270=93163.44000000271=0.0000000055=BTCUSDT25043=8243034669425044=82430347121279=1269=0270=93163.43000000271=0.0000900055=BTCUSDT25043=8243034669425044=82430347121279=1269=0270=93163.25000000271=0.0000000055=BTCUSDT25043=8243034669425044=82430347121279=1269=0270=93163.23000000271=0.0000000055=BTCUSDT25043=8243034669425044=82430347121279=1269=0270=93163.22000000271=0.2477100055=BTCUSDT25043=8243034669425044=82430347121279=1269=0270=93163.18000000271=0.0000000055=BTCUSDT25043=8243034669425044=82430347121279=1269=0270=93163.16000000271=0.3004200055=BTCUSDT25043=8243034669425044=82430347121279=1269=0270=93163.15000000271=0.5086000055=BTCUSDT25043=8243034669425044=82430347121279=1269=0270=93163.00000000271=0.0000600055=BTCUSDT25043=8243034669425044=82430347121279=1269=0270=93162.94000000271=0.0000000055=BTCUSDT25043=8243034669425044=82430347121279=1269=0270=93162.35000000271=0.0000000055=BTCUSDT25043=8243034669425044=82430347121279=1269=0270=93162.11000000271=0.1336200055=BTCUSDT25043=8243034669425044=82430347121279=1269=0270=93162.10000000271=0.0000600055=BTCUSDT25043=8243034669425044=82430347121279=1269=0270=93161.75000000271=0.0000000055=BTCUSDT25043=8243034669425044=82430347121279=1269=0270=93161.64000000271=0.0000600055=BTCUSDT25043=8243034669425044=82430347121279=1269=0270=93160.85000000271=0.0000000055=BTCUSDT25043=8243034669425044=82430347121279=1269=0270=93160.57000000271=0.0824300055=BTCUSDT25043=8243034669425044=82430347121279=1269=0270=93160.21000000271=0.0000000055=BTCUSDT25043=8243034669425044=82430347121279=1269=0270=93159.89000000271=0.0009000055=BTCUSDT25043=8243034669425044=82430347121279=1269=0270=93159.53000000271=0.3004200055=BTCUSDT25043=8243034669425044=82430347121279=1269=0270=93156.71000000271=0.4225800055=BTCUSDT25043=8243034669425044=82430347121279=1269=0270=93153.52000000271=0.0001100055=BTCUSDT25043=8243034669425044=82430347121279=1269=0270=93153.03000000271=1.8112900055=BTCUSDT25043=8243034669425044=82430347121279=1269=0270=93147.82000000271=0.0000600055=BTCUSDT25043=8243034669425044=82430347121279=1269=0270=93145.83000000271=0.0462100055=BTCUSDT25043=8243034669425044=82430347121279=1269=0270=93145.71000000271=0.0418500055=BTCUSDT25043=8243034669425044=82430347121279=1269=0270=93145.56000000271=0.0000000055=BTCUSDT25043=8243034669425044=82430347121279=1269=0270=93142.97000000271=0.0000000055=BTCUSDT25043=8243034669425044=82430347121279=1269=0270=93142.42000000271=0.1187600055=BTCUSDT25043=8243034669425044=82430347121279=1269=0270=93133.14000000271=0.0000000055=BTCUSDT25043=8243034669425044=82430347121279=1269=0270=93130.87000000271=0.1201600055=BTCUSDT25043=8243034669425044=82430347121279=1269=0270=93129.73000000271=0.0000000055=BTCUSDT25043=8243034669425044=82430347121279=1269=0270=93127.33000000271=0.0000000055=BTCUSDT25043=8243034669425044=82430347121279=1269=0270=93122.98000000271=0.0010900055=BTCUSDT25043=8243034669425044=82430347121279=1269=0270=93112.56000000271=0.0000000055=BTCUSDT25043=8243034669425044=82430347121279=1269=0270=93102.85000000271=0.0000000055=BTCUSDT25043=8243034669425044=82430347121279=1269=0270=93097.27000000271=0.3004200055=BTCUSDT25043=8243034669425044=82430347121279=1269=0270=93093.70000000271=0.0001800055=BTCUSDT25043=8243034669425044=82430347121279=1269=0270=93092.01000000271=0.0000000055=BTCUSDT25043=8243034669425044=82430347121279=1269=0270=93089.81000000271=0.0000000055=BTCUSDT25043=8243034669425044=82430347121279=1269=0270=93084.01000000271=0.0001800055=BTCUSDT25043=8243034669425044=82430347121279=1269=0270=93082.86000000271=0.0000000055=BTCUSDT25043=8243034669425044=82430347121279=1269=0270=93082.36000000271=0.0000900055=BTCUSDT25043=8243034669425044=82430347121279=1269=0270=93082.35000000271=0.1461100055=BTCUSDT25043=8243034669425044=82430347121279=1269=0270=93074.89000000271=0.0000000055=BTCUSDT25043=8243034669425044=82430347121279=1269=0270=93067.43000000271=0.0000000055=BTCUSDT25043=8243034669425044=82430347121279=1269=0270=93055.88000000271=0.0000000055=BTCUSDT25043=8243034669425044=82430347121279=1269=0270=93049.35000000271=0.0000000055=BTCUSDT25043=8243034669425044=82430347121279=1269=0270=92930.01000000271=0.0000000055=BTCUSDT25043=8243034669425044=82430347121279=1269=0270=92917.84000000271=0.0000000055=BTCUSDT25043=8243034669425044=82430347121279=1269=0270=92842.29000000271=0.2242800055=BTCUSDT25043=8243034669425044=82430347121279=1269=0270=91765.70000000271=0.0000000055=BTCUSDT25043=8243034669425044=82430347121279=1269=1270=93164.56000000271=0.0000000055=BTCUSDT25043=8243034669425044=82430347121279=1269=1270=93164.57000000271=0.0000000055=BTCUSDT25043=8243034669425044=82430347121279=1269=1270=93165.14000000271=0.0000000055=BTCUSDT25043=8243034669425044=82430347121279=1269=1270=93165.15000000271=0.0046700055=BTCUSDT25043=8243034669425044=82430347121279=1269=1270=93165.16000000271=0.0009000055=BTCUSDT25043=8243034669425044=82430347121279=1269=1270=93165.20000000271=0.0000600055=BTCUSDT25043=8243034669425044=82430347121279=1269=1270=93165.96000000271=0.0001200055=BTCUSDT25043=8243034669425044=82430347121279=1269=1270=93166.53000000271=0.0001200055=BTCUSDT25043=8243034669425044=82430347121279=1269=1270=93166.54000000271=0.0001200055=BTCUSDT25043=8243034669425044=82430347121279=1269=1270=93166.56000000271=0.0177200055=BTCUSDT25043=8243034669425044=82430347121279=1269=1270=93167.45000000271=0.0000600055=BTCUSDT25043=8243034669425044=82430347121279=1269=1270=93167.46000000271=0.0001800055=BTCUSDT25043=8243034669425044=82430347121279=1269=1270=93168.06000000271=0.0000600055=BTCUSDT25043=8243034669425044=82430347121279=1269=1270=93169.44000000271=0.0000000055=BTCUSDT25043=8243034669425044=82430347121279=1269=1270=93171.58000000271=0.0000000055=BTCUSDT25043=8243034669425044=82430347121279=1269=1270=93172.05000000271=0.0002400055=BTCUSDT25043=8243034669425044=82430347121279=1269=1270=93172.30000000271=0.0000000055=BTCUSDT25043=8243034669425044=82430347121279=1269=1270=93172.33000000271=0.0020000055=BTCUSDT25043=8243034669425044=82430347121279=1269=1270=93172.51000000271=0.0000000055=BTCUSDT25043=8243034669425044=82430347121279=1269=1270=93172.53000000271=0.0000000055=BTCUSDT25043=8243034669425044=82430347121279=1269=1270=93172.60000000271=0.0000000055=BTCUSDT25043=8243034669425044=82430347121279=1269=1270=93172.61000000271=0.0000000055=BTCUSDT25043=8243034669425044=82430347121279=1269=1270=93172.62000000271=0.0000000055=BTCUSDT25043=8243034669425044=82430347121279=1269=1270=93172.67000000271=0.0000000055=BTCUSDT25043=8243034669425044=82430347121279=1269=1270=93172.72000000271=0.0000000055=BTCUSDT25043=8243034669425044=82430347121279=1269=1270=93172.73000000271=0.0000000055=BTCUSDT25043=8243034669425044=82430347121279=1269=1270=93172.76000000271=0.0000000055=BTCUSDT25043=8243034669425044=82430347121279=1269=1270=93172.82000000271=0.0000000055=BTCUSDT25043=8243034669425044=82430347121279=1269=1270=93172.95000000271=0.0000000055=BTCUSDT25043=8243034669425044=82430347121279=1269=1270=93173.01000000271=0.0000000055=BTCUSDT25043=8243034669425044=82430347121279=1269=1270=93173.06000000271=0.0000000055=BTCUSDT25043=8243034669425044=82430347121279=1269=1270=93173.16000000271=0.0000000055=BTCUSDT25043=8243034669425044=82430347121279=1269=1270=93173.18000000271=0.0000000055=BTCUSDT25043=8243034669425044=82430347121279=1269=1270=93173.22000000271=0.0005600055=BTCUSDT25043=8243034669425044=82430347121279=1269=1270=93173.62000000271=0.0000000055=BTCUSDT25043=8243034669425044=82430347121279=1269=1270=93173.81000000271=0.0004700055=BTCUSDT25043=8243034669425044=82430347121279=1269=1270=93173.91000000271=0.0000000055=BTCUSDT25043=8243034669425044=82430347121279=1269=1270=93173.97000000271=0.0000000055=BTCUSDT25043=8243034669425044=82430347121279=1269=1270=93174.16000000271=0.0000000055=BTCUSDT25043=8243034669425044=82430347121279=1269=1270=93174.27000000271=0.0000000055=BTCUSDT25043=8243034669425044=82430347121279=1269=1270=93174.36000000271=0.0000000055=BTCUSDT25043=8243034669425044=82430347121279=1269=1270=93174.39000000271=0.0000000055=BTCUSDT25043=8243034669425044=82430347121279=1269=1270=93174.66000000271=0.0000000055=BTCUSDT25043=8243034669425044=82430347121279=1269=1270=93175.40000000271=0.0000000055=BTCUSDT25043=8243034669425044=82430347121279=1269=1270=93175.45000000271=0.0000000055=BTCUSDT25043=8243034669425044=82430347121279=1269=1270=93175.77000000271=0.0000000055=BTCUSDT25043=8243034669425044=82430347121279=1269=1270=93176.02000000271=0.0000000055=BTCUSDT25043=8243034669425044=82430347121279=1269=1270=93176.23000000271=0.0000000055=BTCUSDT25043=8243034669425044=82430347121279=1269=1270=93176.55000000271=0.0000000055=BTCUSDT25043=8243034669425044=82430347121279=1269=1270=93176.58000000271=0.0000000055=BTCUSDT25043=8243034669425044=82430347121279=1269=1270=93176.60000000271=0.0000000055=BTCUSDT25043=8243034669425044=82430347121279=1269=1270=93176.70000000271=0.0000000055=BTCUSDT25043=8243034669425044=82430347121279=1269=1270=93176.75000000271=0.0000000055=BTCUSDT25043=8243034669425044=82430347121279=1269=1270=93177.26000000271=0.1017300055=BTCUSDT25043=8243034669425044=82430347121279=1269=1270=93177.70000000271=0.0000000055=BTCUSDT25043=8243034669425044=82430347121279=1269=1270=93177.97000000271=0.0000000055=BTCUSDT25043=8243034669425044=82430347121279=1269=1270=93179.12000000271=0.0010700055=BTCUSDT25043=8243034669425044=82430347121279=1269=1270=93179.62000000271=0.0000000055=BTCUSDT25043=8243034669425044=82430347121279=1269=1270=93180.58000000271=0.0000000055=BTCUSDT25043=8243034669425044=82430347121279=1269=1270=93180.99000000271=0.0000000055=BTCUSDT25043=8243034669425044=82430347121279=1269=1270=93181.75000000271=0.0000000055=BTCUSDT25043=8243034669425044=82430347121279=1269=1270=93184.66000000271=0.0000000055=BTCUSDT25043=8243034669425044=82430347121279=1269=1270=93184.74000000271=0.0000000055=BTCUSDT25043=8243034669425044=82430347121279=1269=1270=93185.68000000271=0.0000000055=BTCUSDT25043=8243034669425044=82430347121279=1269=1270=93187.43000000271=0.0800000055=BTCUSDT25043=8243034669425044=82430347121279=1269=1270=93188.12000000271=0.0053600055=BTCUSDT25043=8243034669425044=82430347121279=1269=1270=93188.62000000271=0.1207300055=BTCUSDT25043=8243034669425044=82430347121279=1269=1270=93189.68000000271=0.0200000055=BTCUSDT25043=8243034669425044=82430347121279=1269=1270=93196.03000000271=0.0000000055=BTCUSDT25043=8243034669425044=82430347121279=1269=1270=93197.78000000271=0.0025000055=BTCUSDT25043=8243034669425044=82430347121279=1269=1270=93198.07000000271=0.0000000055=BTCUSDT25043=8243034669425044=82430347121279=1269=1270=93199.19000000271=0.0000600055=BTCUSDT25043=8243034669425044=82430347121279=1269=1270=93201.86000000271=0.0000000055=BTCUSDT25043=8243034669425044=82430347121279=1269=1270=93204.01000000271=0.0000000055=BTCUSDT25043=8243034669425044=82430347121279=1269=1270=93207.07000000271=0.0010700055=BTCUSDT25043=8243034669425044=82430347121279=1269=1270=93213.12000000271=0.1207600055=BTCUSDT25043=8243034669425044=82430347121279=1269=1270=93221.26000000271=0.1207100055=BTCUSDT25043=8243034669425044=82430347121279=1269=1270=93224.04000000271=0.1207400055=BTCUSDT25043=8243034669425044=82430347121279=1269=1270=93235.93000000271=0.0000000055=BTCUSDT25043=8243034669425044=82430347121279=1269=1270=93241.14000000271=0.0000000055=BTCUSDT25043=8243034669425044=82430347121279=1269=1270=93243.99000000271=0.0000000055=BTCUSDT25043=8243034669425044=82430347121279=1269=1270=93246.44000000271=0.0308400055=BTCUSDT25043=8243034669425044=82430347121279=1269=1270=93261.50000000271=0.1876500055=BTCUSDT25043=8243034669425044=82430347121279=1269=1270=93261.51000000271=0.0000000055=BTCUSDT25043=8243034669425044=82430347121279=1269=1270=93323.79000000271=0.0000000055=BTCUSDT25043=8243034669425044=82430347121279=1269=1270=93330.80000000271=0.0375600055=BTCUSDT25043=8243034669425044=82430347121279=1269=1270=93330.92000000271=0.0375600055=BTCUSDT25043=8243034669425044=82430347121279=1269=1270=93334.74000000271=0.0000000055=BTCUSDT25043=8243034669425044=82430347121279=1269=1270=93334.75000000271=0.0000000055=BTCUSDT25043=8243034669425044=82430347121279=1269=1270=93383.65000000271=0.0354200055=BTCUSDT25043=8243034669425044=82430347121279=1269=1270=93390.36000000271=0.0309800055=BTCUSDT25043=8243034669425044=82430347121279=1269=1270=94560.61000000271=0.0000000055=BTCUSDT25043=8243034669425044=8243034712110=249